Traceback (most recent call last):
  File "C:\Users\mbrown2\Anaconda3\envs\steve\lib\site-packages\jupyter_cache\executors\utils.py", line 58, in single_nb_execution
    executenb(
  File "C:\Users\mbrown2\Anaconda3\envs\steve\lib\site-packages\nbclient\client.py", line 1305, in execute
    return NotebookClient(nb=nb, resources=resources, km=km, **kwargs).execute()
  File "C:\Users\mbrown2\Anaconda3\envs\steve\lib\site-packages\jupyter_core\utils\__init__.py", line 166, in wrapped
    return loop.run_until_complete(inner)
  File "C:\Users\mbrown2\Anaconda3\envs\steve\lib\asyncio\base_events.py", line 616, in run_until_complete
    return future.result()
  File "C:\Users\mbrown2\Anaconda3\envs\steve\lib\site-packages\nbclient\client.py", line 705, in async_execute
    await self.async_execute_cell(
  File "C:\Users\mbrown2\Anaconda3\envs\steve\lib\site-packages\nbclient\client.py", line 1058, in async_execute_cell
    await self._check_raise_for_error(cell, cell_index, exec_reply)
  File "C:\Users\mbrown2\Anaconda3\envs\steve\lib\site-packages\nbclient\client.py", line 914, in _check_raise_for_error
    raise CellExecutionError.from_cell_and_msg(cell, exec_reply_content)
nbclient.exceptions.CellExecutionError: An error occurred while executing the following cell:
------------------
rh_module = pvdeg.humidity.calc_rel_humidity(weather_df=WEATHER, meta=META)
rh_module.head()
------------------


[1;31m---------------------------------------------------------------------------[0m
[1;31mAttributeError[0m                            Traceback (most recent call last)
Cell [1;32mIn[9], line 1[0m
[1;32m----> 1[0m rh_module [38;5;241m=[39m [43mpvdeg[49m[38;5;241;43m.[39;49m[43mhumidity[49m[38;5;241;43m.[39;49m[43mcalc_rel_humidity[49m(weather_df[38;5;241m=[39mWEATHER, meta[38;5;241m=[39mMETA)
[0;32m      2[0m rh_module[38;5;241m.[39mhead()

[1;31mAttributeError[0m: module 'pvdeg.humidity' has no attribute 'calc_rel_humidity'

