Traceback (most recent call last):
  File "C:\Users\sayala\AppData\Roaming\Python\Python39\site-packages\jupyter_cache\executors\utils.py", line 58, in single_nb_execution
    executenb(
  File "C:\ProgramData\Anaconda3\lib\site-packages\nbclient\client.py", line 1204, in execute
    return NotebookClient(nb=nb, resources=resources, km=km, **kwargs).execute()
  File "C:\ProgramData\Anaconda3\lib\site-packages\nbclient\util.py", line 84, in wrapped
    return just_run(coro(*args, **kwargs))
  File "C:\ProgramData\Anaconda3\lib\site-packages\nbclient\util.py", line 62, in just_run
    return loop.run_until_complete(coro)
  File "C:\ProgramData\Anaconda3\lib\asyncio\base_events.py", line 647, in run_until_complete
    return future.result()
  File "C:\ProgramData\Anaconda3\lib\site-packages\nbclient\client.py", line 663, in async_execute
    await self.async_execute_cell(
  File "C:\ProgramData\Anaconda3\lib\site-packages\nbclient\client.py", line 965, in async_execute_cell
    await self._check_raise_for_error(cell, cell_index, exec_reply)
  File "C:\ProgramData\Anaconda3\lib\site-packages\nbclient\client.py", line 862, in _check_raise_for_error
    raise CellExecutionError.from_cell_and_msg(cell, exec_reply_content)
nbclient.exceptions.CellExecutionError: An error occurred while executing the following cell:
------------------
# load weather and location data, use pvlib read_psm3 function with map_variables = True

sam_file = r'example data\psm3.csv'
weather, meta = pvlib.iotools.read_psm3(sam_file, map_variables = True)
#weather, meta = pvlib.iotools.read_psm3(sam_file)
------------------

[1;31m---------------------------------------------------------------------------[0m
[1;31mFileNotFoundError[0m                         Traceback (most recent call last)
[1;32m~\AppData\Local\Temp\1\ipykernel_27320\416425688.py[0m in [0;36m<module>[1;34m[0m
[0;32m      2[0m [1;33m[0m[0m
[0;32m      3[0m [0msam_file[0m [1;33m=[0m [1;34mr'example data\psm3.csv'[0m[1;33m[0m[1;33m[0m[0m
[1;32m----> 4[1;33m [0mweather[0m[1;33m,[0m [0mmeta[0m [1;33m=[0m [0mpvlib[0m[1;33m.[0m[0miotools[0m[1;33m.[0m[0mread_psm3[0m[1;33m([0m[0msam_file[0m[1;33m,[0m [0mmap_variables[0m [1;33m=[0m [1;32mTrue[0m[1;33m)[0m[1;33m[0m[1;33m[0m[0m
[0m[0;32m      5[0m [1;31m#weather, meta = pvlib.iotools.read_psm3(sam_file)[0m[1;33m[0m[1;33m[0m[0m

[1;32m~\AppData\Roaming\Python\Python39\site-packages\pvlib\iotools\psm3.py[0m in [0;36mread_psm3[1;34m(filename, map_variables)[0m
[0;32m    410[0m        [1;33m<[0m[0mhttps[0m[1;33m:[0m[1;33m//[0m[0mweb[0m[1;33m.[0m[0marchive[0m[1;33m.[0m[0morg[0m[1;33m/[0m[0mweb[0m[1;33m/[0m[1;36m20170207203107[0m[1;33m/[0m[0mhttps[0m[1;33m:[0m[1;33m//[0m[0msam[0m[1;33m.[0m[0mnrel[0m[1;33m.[0m[0mgov[0m[1;33m/[0m[0msites[0m[1;33m/[0m[0mdefault[0m[1;33m/[0m[0mfiles[0m[1;33m/[0m[0mcontent[0m[1;33m/[0m[0mdocuments[0m[1;33m/[0m[0mpdf[0m[1;33m/[0m[0mwfcsv[0m[1;33m.[0m[0mpdf[0m[1;33m>[0m[0;31m`[0m[0m_[0m[1;33m[0m[1;33m[0m[0m
[0;32m    411[0m     """
[1;32m--> 412[1;33m     [1;32mwith[0m [0mopen[0m[1;33m([0m[0mstr[0m[1;33m([0m[0mfilename[0m[1;33m)[0m[1;33m,[0m [1;34m'r'[0m[1;33m)[0m [1;32mas[0m [0mfbuf[0m[1;33m:[0m[1;33m[0m[1;33m[0m[0m
[0m[0;32m    413[0m         [0mcontent[0m [1;33m=[0m [0mparse_psm3[0m[1;33m([0m[0mfbuf[0m[1;33m,[0m [0mmap_variables[0m[1;33m)[0m[1;33m[0m[1;33m[0m[0m
[0;32m    414[0m     [1;32mreturn[0m [0mcontent[0m[1;33m[0m[1;33m[0m[0m

[1;31mFileNotFoundError[0m: [Errno 2] No such file or directory: 'example data\\psm3.csv'
FileNotFoundError: [Errno 2] No such file or directory: 'example data\\psm3.csv'

