Traceback (most recent call last):
  File "C:\Users\sayala\AppData\Roaming\Python\Python311\site-packages\jupyter_cache\executors\utils.py", line 58, in single_nb_execution
    executenb(
  File "C:\Users\sayala\AppData\Roaming\Python\Python311\site-packages\nbclient\client.py", line 1305, in execute
    return NotebookClient(nb=nb, resources=resources, km=km, **kwargs).execute()
           ^^^^^^^^^^^^^^^^^^^^^^^^^^^^^^^^^^^^^^^^^^^^^^^^^^^^^^^^^^^^^^^^^^^^^
  File "C:\ProgramData\Anaconda3\Lib\site-packages\jupyter_core\utils\__init__.py", line 173, in wrapped
    return loop.run_until_complete(inner)
           ^^^^^^^^^^^^^^^^^^^^^^^^^^^^^^
  File "C:\ProgramData\Anaconda3\Lib\asyncio\base_events.py", line 653, in run_until_complete
    return future.result()
           ^^^^^^^^^^^^^^^
  File "C:\Users\sayala\AppData\Roaming\Python\Python311\site-packages\nbclient\client.py", line 705, in async_execute
    await self.async_execute_cell(
  File "C:\Users\sayala\AppData\Roaming\Python\Python311\site-packages\nbclient\client.py", line 1058, in async_execute_cell
    await self._check_raise_for_error(cell, cell_index, exec_reply)
  File "C:\Users\sayala\AppData\Roaming\Python\Python311\site-packages\nbclient\client.py", line 914, in _check_raise_for_error
    raise CellExecutionError.from_cell_and_msg(cell, exec_reply_content)
nbclient.exceptions.CellExecutionError: An error occurred while executing the following cell:
------------------
from pvdeg import letid, collection, utilities, DATA_DIR

import pvlib
import os
import pandas as pd
import numpy as np
import matplotlib.pyplot as plt
import pvdeg
------------------


[1;31m---------------------------------------------------------------------------[0m
[1;31mImportError[0m                               Traceback (most recent call last)
Cell [1;32mIn[2], line 1[0m
[1;32m----> 1[0m [38;5;28;01mfrom[39;00m [38;5;21;01mpvdeg[39;00m [38;5;28;01mimport[39;00m letid, collection, utilities, DATA_DIR
[0;32m      3[0m [38;5;28;01mimport[39;00m [38;5;21;01mpvlib[39;00m
[0;32m      4[0m [38;5;28;01mimport[39;00m [38;5;21;01mos[39;00m

File [1;32m~\Documents\GitHub\PVDegTool\PVDegradationTools\pvdeg\__init__.py:11[0m
[0;32m      9[0m [38;5;28;01mfrom[39;00m [38;5;21;01m.[39;00m [38;5;28;01mimport[39;00m design
[0;32m     10[0m [38;5;28;01mfrom[39;00m [38;5;21;01m.[39;00m [38;5;28;01mimport[39;00m fatigue
[1;32m---> 11[0m [38;5;28;01mfrom[39;00m [38;5;21;01m.[39;00m [38;5;28;01mimport[39;00m geospatial
[0;32m     12[0m [38;5;28;01mfrom[39;00m [38;5;21;01m.[39;00m [38;5;28;01mimport[39;00m humidity
[0;32m     13[0m [38;5;28;01mfrom[39;00m [38;5;21;01m.[39;00m [38;5;28;01mimport[39;00m letid

File [1;32m~\Documents\GitHub\PVDegTool\PVDegradationTools\pvdeg\geospatial.py:28[0m
[0;32m     25[0m [38;5;28;01mimport[39;00m [38;5;21;01mcartopy[39;00m[38;5;21;01m.[39;00m[38;5;21;01mfeature[39;00m [38;5;28;01mas[39;00m [38;5;21;01mcfeature[39;00m
[0;32m     27[0m [38;5;28;01mfrom[39;00m [38;5;21;01mtyping[39;00m [38;5;28;01mimport[39;00m Tuple
[1;32m---> 28[0m [38;5;28;01mfrom[39;00m [38;5;21;01mshapely[39;00m [38;5;28;01mimport[39;00m LineString, MultiLineString
[0;32m     31[0m [38;5;28;01mdef[39;00m [38;5;21mstart_dask[39m(hpc[38;5;241m=[39m[38;5;28;01mNone[39;00m):
[0;32m     32[0m [38;5;250m    [39m[38;5;124;03m"""[39;00m
[0;32m     33[0m [38;5;124;03m    Starts a dask cluster for parallel processing.[39;00m
[0;32m     34[0m 
[1;32m   (...)[0m
[0;32m     70[0m [38;5;124;03m        Dask client object.[39;00m
[0;32m     71[0m [38;5;124;03m    """[39;00m

[1;31mImportError[0m: cannot import name 'LineString' from 'shapely' (C:\Users\sayala\AppData\Roaming\Python\Python311\site-packages\shapely\__init__.py)

